Workbook

Sheet Histori
A1: TA | B1: Semester | C1: Kode Mata Kuliah | D1: sks | E1: Nama Mata Kuliah | F1: Kelas | G1: Kuota | H1: Sesi Kelas | I1: Hari | J1: Jam Mulai | K1: Jam Selesai | L1: Bentuk Pembelajaran | M1: Jenis Pertemuan | N1: NIK Dosen | O1: Nama Dosen | P1: Jenis Dosen | Q1: Beban sks | R1: Kebutuhan Khusus Dosen | S1: Kebutuhan Khusus Mahasiswa | T1: Fasilitas Khusus Ruangan | U1: Ruangan (khusus untuk Praktikum) | V1: Dosen Koordinator
A3: 2024 | B3: 1 | C3: AIF231101 | D3: 4 | E3: Matematika Dasar | F3: B | G3: 40 | H3: 2 | I3: Kamis | J3: 08:00 | K3: 10:00 | L3: Kuliah | M3: Kuliah Mimbar | N3: 20050254 | O3: Luciana Abednego S.Kom., M.T. | P3: Dosen | Q3: 2 | R3: - | S3: - | T3: - | V3: Luciana Abednego S.Kom., M.T.
A4: 2024 | B4: 1 | C4: AIF231101 | D4: 4 | E4: Matematika Dasar | F4: C | G4: 40 | H4: 2 | I4: Kamis | J4: 15:00 | K4: 17:00 | L4: Kuliah | M4: Kuliah Mimbar | N4: 20050254 | O4: Luciana Abednego S.Kom., M.T. | P4: Dosen | Q4: 2 | R4: Umur | S4: - | T4: - | V4: Luciana Abednego S.Kom., M.T.
A5: 2024 | B5: 1 | C5: AIF231101 | D5: 4 | E5: Matematika Dasar | F5: A | G5: 40 | H5: 2 | I5: Kamis | J5: 15:00 | K5: 17:00 | L5: Kuliah | M5: Kuliah Mimbar | N5: 19850271 | O5: Rosa De Lima Endang Padmowati Dra., M.T. | P5: Dosen | Q5: 2 | R5: Umur | S5: - | T5: - | V5: Luciana Abednego S.Kom., M.T.
A6: 2024 | B6: 1 | C6: AIF231101 | D6: 4 | E6: Matematika Dasar | F6: A | G6: 40 | H6: 1 | I6: Selasa | J6: 13:00 | K6: 15:00 | L6: Kuliah | M6: Kuliah Mimbar | N6: 19850271 | O6: Rosa De Lima Endang Padmowati Dra., M.T. | P6: Dosen | Q6: 2 | R6: Umur | S6: - | T6: - | V6: Luciana Abednego S.Kom., M.T.
A7: 2024 | B7: 1 | C7: AIF231101 | D7: 4 | E7: Matematika Dasar | F7: B | G7: 40 | H7: 1 | I7: Selasa | J7: 15:00 | K7: 17:00 | L7: Kuliah | M7: Kuliah Mimbar | N7: 19850271 | O7: Rosa De Lima Endang Padmowati Dra., M.T. | P7: Dosen | Q7: 2 | R7: Umur | S7: - | T7: - | V7: Luciana Abednego S.Kom., M.T.
A8: 2024 | B8: 1 | C8: AIF231101 | D8: 4 | E8: Matematika Dasar | F8: C | G8: 40 | H8: 1 | I8: Selasa | J8: 08:00 | K8: 10:00 | L8: Kuliah | M8: Kuliah Mimbar | N8: 19850271 | O8: Rosa De Lima Endang Padmowati Dra., M.T. | P8: Dosen | Q8: 2 | R8: - | S8: - | T8: - | V8: Luciana Abednego S.Kom., M.T.
A9: 2024 | B9: 1 | C9: AIF231103 | D9: 4 | E9: Dasar Pemrograman | F9: B | G9: 35 | H9: 3 | I9: Jumat | J9: 09:00 | K9: 11:00 | L9: Kuliah | M9: Kuliah Mimbar | N9: 20050346 | O9: Joanna Helga S.Kom., M.Sc. | P9: Dosen | Q9: 2 | R9: - | S9: - | T9: - | V9: Husnul Hakim S.Kom., M.T.
A10: 2024 | B10: 1 | C10: AIF231103 | D10: 4 | E10: Dasar Pemrograman | F10: B | G10: 35 | H10: 2 | I10: Rabu | J10: 08:00 | K10: 10:00 | L10: Praktikum | M10: Kuliah Mimbar | N10: 20050346 | O10: Joanna Helga S.Kom., M.Sc. | P10: Dosen | Q10: 1 | R10: - | S10: - | T10: - | V10: Husnul Hakim S.Kom., M.T.
A11: 2024 | B11: 1 | C11: AIF231103 | D11: 4 | E11: Dasar Pemrograman | F11: B | G11: 35 | H11: 1 | I11: Senin | J11: 10:00 | K11: 12:00 | L11: Kuliah | M11: Kuliah Mimbar | N11: 20050346 | O11: Joanna Helga S.Kom., M.Sc. | P11: Dosen | Q11: 2 | R11: - | S11: - | T11: - | V11: Husnul Hakim S.Kom., M.T.
A12: 2024 | B12: 1 | C12: AIF231103 | D12: 4 | E12: Dasar Pemrograman | F12: C | G12: 35 | H12: 2 | I12: Rabu | J12: 08:00 | K12: 10:00 | L12: Praktikum | M12: Kuliah Mimbar | N12: 20240354 | O12: Wilona Theodora Muliadi | P12: Asisten Dosen | Q12: 1 | R12: - | S12: - | T12: - | V12: Husnul Hakim S.Kom., M.T.
A13: 2024 | B13: 1 | C13: AIF231103 | D13: 4 | E13: Dasar Pemrograman | F13: A | G13: 35 | H13: 2 | I13: Rabu | J13: 08:00 | K13: 10:00 | L13: Praktikum | M13: Kuliah Mimbar | N13: 20240351 | O13: Arlo Dante Hananvyasa | P13: Asisten Dosen | Q13: 1 | R13: - | S13: - | T13: - | V13: Husnul Hakim S.Kom., M.T.
A14: 2024 | B14: 1 | C14: AIF231103 | D14: 4 | E14: Dasar Pemrograman | F14: B | G14: 35 | H14: 2 | I14: Rabu | J14: 08:00 | K14: 10:00 | L14: Praktikum | M14: Kuliah Mimbar | N14: 20240245 | O14: Gabriela Ivy Effendi | P14: Asisten Dosen | Q14: 1 | R14: - | S14: - | T14: - | V14: Husnul Hakim S.Kom., M.T.
... A113: 2024 | B113: 1 | C113: AIF233112 | D113: 3 | E113: Pemrograman Kompetitif 5 | F113: A | G113: 35 | H113: 1 | I113: Selasa | J113: 13:00 | K113: 16:00 | L113: Kuliah | M113: Kuliah Mimbar | N113: 20050346 | O113: Joanna Helga S.Kom., M.Sc. | P113: Dosen | Q113: 3 | R113: - | S113: - | T113: - | V113: Lionov Ph.D.
A114: 2024 | B114: 1 | C114: AIF233113 | D114: 2 | E114: Kerja Praktik Computing Science 1 | F114: A | G114: 60 | H114: 1 | I114: Sabtu | J114: 10:00 | K114: 11:00 | L114: Praktik Lapangan | N114: 20130009 | O114: Husnul Hakim S.Kom., M.T. | P114: Dosen | Q114: 1 | R114: - | S114: - | T114: - | V114: Husnul Hakim S.Kom., M.T.
A115: 2024 | B115: 1 | C115: AIF233115 | D115: 3 | E115: Kerja Praktik Computing Science 2 | F115: A | G115: 60 | H115: 1 | I115: Sabtu | J115: 08:00 | K115: 09:00 | L115: Praktik Lapangan | N115: 20130009 | O115: Husnul Hakim S.Kom., M.T. | P115: Dosen | Q115: 1 | R115: - | S115: - | T115: - | V115: Husnul Hakim S.Kom., M.T.
A116: 2024 | B116: 1 | C116: AIF233117 | D116: 4 | E116: Kerja Praktik Computing Science 3 | F116: A | G116: 60 | H116: 1 | I116: Sabtu | J116: 11:00 | K116: 12:00 | L116: Kuliah | N116: 20130009 | O116: Husnul Hakim S.Kom., M.T. | P116: Dosen | Q116: 1 | R116: - | S116: - | T116: - | V116: Husnul Hakim S.Kom., M.T.
A117: 2024 | B117: 1 | C117: AIF233119 | D117: 5 | E117: Kerja Praktik Computing Science 4 | I117: Tidak Ada | N117: - | O117: - | P117: - | R117: - | S117: - | T117: - | V117: Husnul Hakim S.Kom., M.T.
A118: 2024 | B118: 1 | C118: AIF233127 | D118: 3 | E118: Proyek Pengembangan Games | F118: A | G118: 35 | H118: 1 | I118: Selasa | J118: 15:00 | K118: 18:00 | L118: Kuliah | M118: Kuliah Mimbar | N118: 20190013 | O118: Jefvin Viriya S.T. | P118: Dosen | Q118: 3 | R118: - | S118: - | T118: - | V118: Mariskha Tri Adithia S.Si., M.Sc., PDEng.
A119: 2024 | B119: 1 | C119: AIF233131 | D119: 3 | E119: Pemrograman Go | F119: A | G119: 35 | H119: 1 | I119: Rabu | J119: 12:30 | K119: 15:00 | L119: Kuliah | M119: Kuliah Mimbar | N119: 20160127 | O119: Keenan Adiwijaya Leman S.T., M.T. | P119: Dosen | Q119: 2 | R119: - | S119: - | T119: - | V119: Keenan Adiwijaya Leman S.T., M.T.
A120: 2024 | B120: 1 | C120: AIF233131 | D120: 3 | E120: Pemrograman Go | F120: A | G120: 35 | H120: 1 | I120: Rabu | J120: 12:30 | K120: 15:00 | L120: Kuliah | M120: Kuliah Mimbar | N120: 20030252 | O120: Lionov Ph.D. | P120: Dosen | Q120: 1 | R120: - | S120: - | T120: - | V120: Keenan Adiwijaya Leman S.T., M.T.
A121: 2024 | B121: 1 | C121: AIF233201 | D121: 3 | E121: Pemrograman Berbasis Web | F121: A | G121: 35 | H121: 1 | I121: Senin | J121: 10:00 | K121: 12:30 | L121: Kuliah | M121: Kuliah Mimbar | N121: 20120135 | O121: Raymond Chandra Putra S.T., M.T. | P121: Dosen | Q121: 3 | R121: - | S121: - | T121: - | V121: Raymond Chandra Putra S.T., M.T.
A122: 2024 | B122: 1 | C122: AIF233201 | D122: 3 | E122: Pemrograman Berbasis Web | F122: A | G122: 35 | H122: 2 | I122: Kamis | J122: 10:00 | K122: 12:00 | L122: Praktikum | M122: Kuliah Mimbar | N122: 20120135 | O122: Raymond Chandra Putra S.T., M.T. | P122: Dosen | Q122: 1 | R122: - | S122: - | T122: - | V122: Raymond Chandra Putra S.T., M.T.
A123: 2024 | B123: 1 | C123: AIF233201 | D123: 3 | E123: Pemrograman Berbasis Web | F123: C | G123: 35 | H123: 1 | I123: Senin | J123: 10:00 | K123: 12:30 | L123: Kuliah | M123: Kuliah Mimbar | N123: 20120010 | O123: Pascal Alfadian Nugroho S.Kom., M.Comp. | P123: Dosen | Q123: 3 | R123: - | S123: - | T123: - | V123: Raymond Chandra Putra S.T., M.T.
A124: 2024 | B124: 1 | C124: AIF233201 | D124: 3 | E124: Pemrograman Berbasis Web | F124: B | G124: 35 | H124: 2 | I124: Kamis | J124: 10:00 | K124: 12:00 | L124: Praktikum | M124: Kuliah Mimbar | N124: 20240121 | O124: Reinhart Wilson S. Kom. | P124: Asisten Dosen | Q124: 1 | R124: - | S124: - | T124: - | V124: Raymond Chandra Putra S.T., M.T.
A125: 2024 | B125: 1 | C125: AIF233201 | D125: 3 | E125: Pemrograman Berbasis Web | F125: C | G125: 35 | H125: 2 | I125: Kamis | J125: 10:00 | K125: 12:00 | L125: Praktikum | M125: Kuliah Mimbar | N125: 20240125 | O125: Ignaz Arif Avelino | P125: Asisten Dosen | Q125: 1 | R125: - | S125: - | T125: - | V125: Raymond Chandra Putra S.T., M.T.
A126: 2024 | B126: 1 | C126: AIF233201 | D126: 3 | E126: Pemrograman Berbasis Web | F126: C | G126: 35 | H126: 2 | I126: Kamis | J126: 10:00 | K126: 12:00 | L126: Praktikum | M126: Kuliah Mimbar | N126: 20120010 | O126: Pascal Alfadian Nugroho S.Kom., M.Comp. | P126: Dosen | Q126: 1 | R126: - | S126: - | T126: - | V126: Raymond Chandra Putra S.T., M.T.
A127: 2024 | B127: 1 | C127: AIF233201 | D127: 3 | E127: Pemrograman Berbasis Web | F127: B | G127: 35 | H127: 2 | I127: Kamis | J127: 10:00 | K127: 12:00 | L127: Praktikum | M127: Kuliah Mimbar | N127: 20230306 | O127: Naomi Elianora | P127: Asisten Dosen | Q127: 1 | R127: - | S127: - | T127: - | V127: Raymond Chandra Putra S.T., M.T.
A128: 2024 | B128: 1 | C128: AIF233201 | D128: 3 | E128: Pemrograman Berbasis Web | F128: C | G128: 35 | H128: 2 | I128: Kamis | J128: 10:00 | K128: 12:00 | L128: Praktikum | M128: Kuliah Mimbar | N128: 20230304 | O128: Miroslav Matthew Alva | P128: Asisten Dosen | Q128: 1 | R128: - | S128: - | T128: - | V128: Raymond Chandra Putra S.T., M.T.
A129: 2024 | B129: 1 | C129: AIF233201 | D129: 3 | E129: Pemrograman Berbasis Web | F129: A | G129: 35 | H129: 2 | I129: Kamis | J129: 10:00 | K129: 12:00 | L129: Praktikum | M129: Kuliah Mimbar | N129: 20230184 | O129: William Arthur Sandy Kurniawan | P129: Asisten Dosen | Q129: 1 | R129: - | S129: - | T129: - | V129: Raymond Chandra Putra S.T., M.T.
... A141: 2024 | B141: 1 | C141: AIF233403 | D141: 3 | E141: Sistem Big Data untuk Organisasi | F141: A | G141: 40 | H141: 1 | I141: Jumat | J141: 09:00 | K141: 11:30 | L141: Kuliah | M141: Kuliah Mimbar | N141: 19990894 | O141: Dr. Gede Karya S.T., S.E., M.T. CISA., MPr. | P141: Dosen | Q141: 3 | R141: - | S141: - | T141: - | V141: Dr. Gede Karya S.T., S.E., M.T. CISA., MPr.
A142: 2024 | B142: 1 | C142: AIF233407 | D142: 2 | E142: Kerja Praktik Data Science 1 | I142: Tidak Ada | N142: - | O142: - | P142: - | R142: - | S142: - | T142: - | V142: Husnul Hakim S.Kom., M.T.
A143: 2024 | B143: 1 | C143: AIF233409 | D143: 3 | E143: Kerja Praktik Data Science 2 | I143: Tidak Ada | N143: - | O143: - | P143: - | R143: - | S143: - | T143: - | V143: Husnul Hakim S.Kom., M.T.
A144: 2024 | B144: 1 | C144: AIF233411 | D144: 4 | E144: Kerja Praktik Data Science 3 | I144: Tidak Ada | N144: - | O144: - | P144: - | R144: - | S144: - | T144: - | V144: Husnul Hakim S.Kom., M.T.
A145: 2024 | B145: 1 | C145: AIF233413 | D145: 5 | E145: Kerja Praktik Data Science 4 | I145: Tidak Ada | N145: - | O145: - | P145: - | R145: - | S145: - | T145: - | V145: Husnul Hakim S.Kom., M.T.
A146: 2024 | B146: 1 | C146: AIF233414 | D146: 3 | E146: Pengantar Data Mining dengan Python | F146: A | G146: 35 | H146: 1 | I146: Rabu | J146: 12:30 | K146: 15:00 | L146: Kuliah | M146: Kuliah Mimbar | N146: 20010991 | O146: Prof. Dr. Veronica Sri Moertini Ir., M.T. | P146: Dosen | Q146: 0.5 | R146: - | S146: - | T146: - | V146: Prof. Dr. Veronica Sri Moertini Ir., M.T.
A147: 2024 | B147: 1 | C147: AIF233414 | D147: 3 | E147: Pengantar Data Mining dengan Python | F147: A | G147: 35 | H147: 1 | I147: Rabu | J147: 12:30 | K147: 15:00 | L147: Kuliah | M147: Kuliah Mimbar | N147: 20140307 | O147: Adrian Aldo Bagaskara S.T. | P147: Dosen | Q147: 2.5 | R147: - | S147: - | T147: - | V147: Prof. Dr. Veronica Sri Moertini Ir., M.T.
A148: 2024 | B148: 1 | C148: AIF234001 | D148: 3 | E148: Tugas Akhir 1 | F148: A | G148: 45 | H148: 1 | I148: Kamis | J148: 07:00 | K148: 08:00 | L148: Kuliah | M148: Kuliah Mimbar | N148: 20100037 | O148: Mariskha Tri Adithia S.Si., M.Sc., PDEng. | P148: Dosen | Q148: 1 | R148: - | S148: - | T148: Proyektor dan minimum dua buah papan tulis besar | V148: Mariskha Tri Adithia S.Si., M.Sc., PDEng.
A149: 2024 | B149: 1 | C149: AIF234001 | D149: 3 | E149: Tugas Akhir 1 | F149: A | G149: 45 | H149: 2 | I149: Kamis | J149: 08:00 | K149: 10:00 | L149: Kuliah | M149: Kuliah Mimbar | N149: 20030252 | O149: Lionov Ph.D. | P149: Dosen | Q149: 2 | R149: - | S149: - | T149: - | V149: Mariskha Tri Adithia S.Si., M.Sc., PDEng.
A150: 2024 | B150: 1 | C150: AIF234002 | D150: 6 | E150: Tugas Akhir 2 | F150: A | G150: 45 | H150: 1 | I150: Kamis | J150: 07:00 | K150: 08:00 | L150: Kuliah | M150: Kuliah Mimbar | N150: 20100037 | O150: Mariskha Tri Adithia S.Si., M.Sc., PDEng. | P150: Dosen | Q150: 1 | R150: - | S150: - | T150: - | V150: Mariskha Tri Adithia S.Si., M.Sc., PDEng.
...

Sheet Template
A1: No | B1: TA | C1: Semester | D1: Kode Mata Kuliah | E1: sks | F1: Nama Mata Kuliah | G1: Kelas | H1: Kuota | I1: Sesi Kelas | J1: Hari | K1: Jam Mulai | L1: Jam Selesai | M1: Bentuk Pembelajaran | N1: Jenis Pertemuan | O1: NIK Dosen | P1: Nama Dosen | Q1: Cek Bentrok | R1: Jenis Dosen | S1: Beban sks | T1: Kebutuhan Khusus Dosen | U1: Kebutuhan Khusus Mahasiswa | V1: Fasilitas Khusus Ruangan | W1: Ruangan (khusus untuk Praktikum) | X1: Dosen Koordinator
A2: 3 | B2: 2025 | C2: 1 | D2: AIF231101 | E2: =IFERROR(VLOOKUP(D2, 'Mata Kuliah'!$F$2:$H$2828, 2, FALSE), "") -> 4 | F2: =IFERROR(VLOOKUP(D2, 'Mata Kuliah'!$F$2:$H$2828, 3, FALSE), "") -> Matematika Dasar | G2: B | H2: 50 | I2: 1 | J2: Selasa | K2: 0.54166667 | L2: 0.625 | M2: Kuliah | N2: Kuliah Mimbar | O2: 19850271 | P2: =IFERROR(VLOOKUP(O2, 'Data Dosen'!$A$2:$B$3628, 2, FALSE), "") -> Rosa De Lima Endang Padmowati Dra., M.T. | Q2: =IF(COUNTIFS(O:O,O2,J:J,J2,K:K,"<"&L2,L:L,">"&K2)>1,"Jadwal Bentrok dengan baris lain","Tidak Bentrok") -> Tidak Bentrok | R2: Dosen | S2: 2 | T2: Umur | U2: - | V2: - | X2: Luciana Abednego S.Kom., M.T.
A3: 4 | B3: 2025 | C3: 1 | D3: AIF231101 | E3: =IFERROR(VLOOKUP(D3, 'Mata Kuliah'!$F$2:$H$2828, 2, FALSE), "") -> 4 | F3: =IFERROR(VLOOKUP(D3, 'Mata Kuliah'!$F$2:$H$2828, 3, FALSE), "") -> Matematika Dasar | G3: B | H3: 50 | I3: 2 | J3: Kamis | K3: 0.625 | L3: 0.70833333 | M3: Kuliah | N3: Kuliah Mimbar | O3: 19850271 | P3: =IFERROR(VLOOKUP(O3, 'Data Dosen'!$A$2:$B$3628, 2, FALSE), "") -> Rosa De Lima Endang Padmowati Dra., M.T. | Q3: =IF(COUNTIFS(O:O,O3,J:J,J3,K:K,"<"&L3,L:L,">"&K3)>1,"Jadwal Bentrok dengan baris lain","Tidak Bentrok") -> Tidak Bentrok | R3: Dosen | S3: 2 | T3: Umur | U3: - | V3: - | X3: Luciana Abednego S.Kom., M.T.
A4: 1 | B4: 2025 | C4: 1 | D4: AIF231101 | E4: =IFERROR(VLOOKUP(D4, 'Mata Kuliah'!$F$2:$H$2828, 2, FALSE), "") -> 4 | F4: =IFERROR(VLOOKUP(D4, 'Mata Kuliah'!$F$2:$H$2828, 3, FALSE), "") -> Matematika Dasar | G4: A | H4: 50 | I4: 1 | J4: Selasa | K4: 0.54166667 | L4: 0.625 | M4: Kuliah | N4: Kuliah Mimbar | O4: 20050254 | P4: =IFERROR(VLOOKUP(O4, 'Data Dosen'!$A$2:$B$3628, 2, FALSE), "") -> Luciana Abednego S.Kom., M.T. | Q4: =IF(COUNTIFS(O:O,O4,J:J,J4,K:K,"<"&L4,L:L,">"&K4)>1,"Jadwal Bentrok dengan baris lain","Tidak Bentrok") -> Tidak Bentrok | R4: Dosen | S4: 2 | T4: - | U4: - | V4: - | X4: Luciana Abednego S.Kom., M.T.
A5: 2 | B5: 2025 | C5: 1 | D5: AIF231101 | E5: =IFERROR(VLOOKUP(D5, 'Mata Kuliah'!$F$2:$H$2828, 2, FALSE), "") -> 4 | F5: =IFERROR(VLOOKUP(D5, 'Mata Kuliah'!$F$2:$H$2828, 3, FALSE), "") -> Matematika Dasar | G5: A | H5: 50 | I5: 2 | J5: Kamis | K5: 0.625 | L5: 0.70833333 | M5: Kuliah | N5: Kuliah Mimbar | O5: 20050254 | P5: =IFERROR(VLOOKUP(O5, 'Data Dosen'!$A$2:$B$3628, 2, FALSE), "") -> Luciana Abednego S.Kom., M.T. | Q5: =IF(COUNTIFS(O:O,O5,J:J,J5,K:K,"<"&L5,L:L,">"&K5)>1,"Jadwal Bentrok dengan baris lain","Tidak Bentrok") -> Tidak Bentrok | R5: Dosen | S5: 2 | T5: - | U5: - | V5: - | X5: Luciana Abednego S.Kom., M.T.
A6: 5 | B6: 2025 | C6: 1 | D6: AIF231103 | E6: =IFERROR(VLOOKUP(D6, 'Mata Kuliah'!$F$2:$H$2828, 2, FALSE), "") -> 4 | F6: =IFERROR(VLOOKUP(D6, 'Mata Kuliah'!$F$2:$H$2828, 3, FALSE), "") -> Dasar Pemrograman | G6: A | H6: 35 | I6: 1 | J6: Senin | K6: 0.41666667 | L6: 0.5 | M6: Kuliah | N6: Kuliah Mimbar | O6: 20030252 | P6: =IFERROR(VLOOKUP(O6, 'Data Dosen'!$A$2:$B$3628, 2, FALSE), "") -> Lionov Ph.D. | Q6: =IF(COUNTIFS(O:O,O6,J:J,J6,K:K,"<"&L6,L:L,">"&K6)>1,"Jadwal Bentrok dengan baris lain","Tidak Bentrok") -> Tidak Bentrok | R6: Dosen | S6: 2 | T6: - | U6: - | V6: - | X6: Lionov Ph.D.
A7: 8 | B7: 2025 | C7: 1 | D7: AIF231103 | E7: =IFERROR(VLOOKUP(D7, 'Mata Kuliah'!$F$2:$H$2828, 2, FALSE), "") -> 4 | F7: =IFERROR(VLOOKUP(D7, 'Mata Kuliah'!$F$2:$H$2828, 3, FALSE), "") -> Dasar Pemrograman | G7: B | H7: 45 | I7: 1 | J7: Senin | K7: 0.41666667 | L7: 0.5 | M7: Kuliah | N7: Kuliah Mimbar | O7: 20130009 | P7: =IFERROR(VLOOKUP(O7, 'Data Dosen'!$A$2:$B$3628, 2, FALSE), "") -> Husnul Hakim S.Kom., M.T. | Q7: =IF(COUNTIFS(O:O,O7,J:J,J7,K:K,"<"&L7,L:L,">"&K7)>1,"Jadwal Bentrok dengan baris lain","Tidak Bentrok") -> Tidak Bentrok | R7: Dosen | S7: 2 | T7: - | U7: - | V7: - | X7: Lionov Ph.D.
A8: 10 | B8: 2025 | C8: 1 | D8: AIF231103 | E8: =IFERROR(VLOOKUP(D8, 'Mata Kuliah'!$F$2:$H$2828, 2, FALSE), "") -> 4 | F8: =IFERROR(VLOOKUP(D8, 'Mata Kuliah'!$F$2:$H$2828, 3, FALSE), "") -> Dasar Pemrograman | G8: B | H8: 45 | I8: 3 | J8: Jumat | K8: 0.375 | L8: 0.45833333 | M8: Kuliah | N8: Kuliah Mimbar | O8: 20130009 | P8: =IFERROR(VLOOKUP(O8, 'Data Dosen'!$A$2:$B$3628, 2, FALSE), "") -> Husnul Hakim S.Kom., M.T. | Q8: =IF(COUNTIFS(O:O,O8,J:J,J8,K:K,"<"&L8,L:L,">"&K8)>1,"Jadwal Bentrok dengan baris lain","Tidak Bentrok") -> Tidak Bentrok | R8: Dosen | S8: 2 | T8: - | U8: - | V8: - | X8: Lionov Ph.D.
A9: 7 | B9: 2025 | C9: 1 | D9: AIF231103 | E9: =IFERROR(VLOOKUP(D9, 'Mata Kuliah'!$F$2:$H$2828, 2, FALSE), "") -> 4 | F9: =IFERROR(VLOOKUP(D9, 'Mata Kuliah'!$F$2:$H$2828, 3, FALSE), "") -> Dasar Pemrograman | G9: A | H9: 35 | I9: 3 | J9: Jumat | K9: 0.375 | L9: 0.45833333 | M9: Kuliah | N9: Kuliah Mimbar | O9: 20140323 | P9: =IFERROR(VLOOKUP(O9, 'Data Dosen'!$A$2:$B$3628, 2, FALSE), "") -> Aditya Bagoes Saputra S.T., M.T. | Q9: =IF(COUNTIFS(O:O,O9,J:J,J9,K:K,"<"&L9,L:L,">"&K9)>1,"Jadwal Bentrok dengan baris lain","Tidak Bentrok") -> Tidak Bentrok | R9: Dosen | S9: 2 | T9: - | U9: - | V9: - | X9: Lionov Ph.D.
A10: 6 | B10: 2025 | C10: 1 | D10: AIF231103 | E10: =IFERROR(VLOOKUP(D10, 'Mata Kuliah'!$F$2:$H$2828, 2, FALSE), "") -> 4 | F10: =IFERROR(VLOOKUP(D10, 'Mata Kuliah'!$F$2:$H$2828, 3, FALSE), "") -> Dasar Pemrograman | G10: A | H10: 35 | I10: 2 | J10: Rabu | K10: 0.54166667 | L10: 0.625 | M10: Praktikum | N10: Diskusi Kelompok | O10: 20030252 | P10: =IFERROR(VLOOKUP(O10, 'Data Dosen'!$A$2:$B$3628, 2, FALSE), "") -> Lionov Ph.D. | Q10: =IF(COUNTIFS(O:O,O10,J:J,J10,K:K,"<"&L10,L:L,">"&K10)>1,"Jadwal Bentrok dengan baris lain","Tidak Bentrok") -> Tidak Bentrok | R10: Dosen | S10: 1 | T10: - | U10: - | V10: - | W10: Lab. Komputasi IF 9016 | X10: Lionov Ph.D.
A11: 9 | B11: 2025 | C11: 1 | D11: AIF231103 | E11: =IFERROR(VLOOKUP(D11, 'Mata Kuliah'!$F$2:$H$2828, 2, FALSE), "") -> 4 | F11: =IFERROR(VLOOKUP(D11, 'Mata Kuliah'!$F$2:$H$2828, 3, FALSE), "") -> Dasar Pemrograman | G11: B | H11: 45 | I11: 2 | J11: Rabu | K11: 0.54166667 | L11: 0.625 | M11: Praktikum | N11: Diskusi Kelompok | O11: 20140307 | P11: =IFERROR(VLOOKUP(O11, 'Data Dosen'!$A$2:$B$3628, 2, FALSE), "") -> Adrian Aldo Bagaskara S.T. | Q11: =IF(COUNTIFS(O:O,O11,J:J,J11,K:K,"<"&L11,L:L,">"&K11)>1,"Jadwal Bentrok dengan baris lain","Tidak Bentrok") -> Tidak Bentrok | R11: Dosen | S11: 1 | T11: - | U11: - | V11: - | W11: Lab. Komputasi IF 9017 | X11: Lionov Ph.D.
A12: 15 | B12: 2025 | C12: 1 | D12: AIF231104 | E12: =IFERROR(VLOOKUP(D12, 'Mata Kuliah'!$F$2:$H$2828, 2, FALSE), "") -> 4 | F12: =IFERROR(VLOOKUP(D12, 'Mata Kuliah'!$F$2:$H$2828, 3, FALSE), "") -> Algoritma dan Pemrograman | G12: A | H12: 45 | I12: 1 | J12: Senin | K12: 0.54166667 | L12: 0.625 | M12: Kuliah | N12: Kuliah Mimbar | O12: 20090005 | P12: =IFERROR(VLOOKUP(O12, 'Data Dosen'!$A$2:$B$3628, 2, FALSE), "") -> Vania Natali S.Kom., M.T. | Q12: =IF(COUNTIFS(O:O,O12,J:J,J12,K:K,"<"&L12,L:L,">"&K12)>1,"Jadwal Bentrok dengan baris lain","Tidak Bentrok") -> Tidak Bentrok | R12: Dosen | S12: 2 | T12: - | U12: - | V12: - | X12: Vania Natali S.Kom., M.T.
A13: 17 | B13: 2025 | C13: 1 | D13: AIF231104 | E13: =IFERROR(VLOOKUP(D13, 'Mata Kuliah'!$F$2:$H$2828, 2, FALSE), "") -> 4 | F13: =IFERROR(VLOOKUP(D13, 'Mata Kuliah'!$F$2:$H$2828, 3, FALSE), "") -> Algoritma dan Pemrograman | G13: A | H13: 45 | I13: 3 | J13: Jumat | K13: 0.54166667 | L13: 0.625 | M13: Kuliah | N13: Kuliah Mimbar | O13: 20090005 | P13: =IFERROR(VLOOKUP(O13, 'Data Dosen'!$A$2:$B$3628, 2, FALSE), "") -> Vania Natali S.Kom., M.T. | Q13: =IF(COUNTIFS(O:O,O13,J:J,J13,K:K,"<"&L13,L:L,">"&K13)>1,"Jadwal Bentrok dengan baris lain","Tidak Bentrok") -> Tidak Bentrok | R13: Dosen | S13: 2 | T13: - | U13: - | V13: - | X13: Vania Natali S.Kom., M.T.
A14: 16 | B14: 2025 | C14: 1 | D14: AIF231104 | E14: =IFERROR(VLOOKUP(D14, 'Mata Kuliah'!$F$2:$H$2828, 2, FALSE), "") -> 4 | F14: =IFERROR(VLOOKUP(D14, 'Mata Kuliah'!$F$2:$H$2828, 3, FALSE), "") -> Algoritma dan Pemrograman | G14: A | H14: 45 | I14: 2 | J14: Rabu | K14: 0.41666667 | L14: 0.5 | M14: Praktikum | N14: Diskusi Kelompok | O14: 20110100 | P14: =IFERROR(VLOOKUP(O14, 'Data Dosen'!$A$2:$B$3628, 2, FALSE), "") -> Natalia S.Si., M.Si. | Q14: =IF(COUNTIFS(O:O,O14,J:J,J14,K:K,"<"&L14,L:L,">"&K14)>1,"Jadwal Bentrok dengan baris lain","Tidak Bentrok") -> Tidak Bentrok | R14: Dosen | S14: 1 | T14: - | U14: - | V14: - | W14: Lab. Komputasi IF 9017 | X14: Vania Natali S.Kom., M.T.
A15: 12 | B15: 2025 | C15: 1 | D15: AIF231105 | E15: =IFERROR(VLOOKUP(D15, 'Mata Kuliah'!$F$2:$H$2828, 2, FALSE), "") -> 4 | F15: =IFERROR(VLOOKUP(D15, 'Mata Kuliah'!$F$2:$H$2828, 3, FALSE), "") -> Matematika Diskret | G15: A | H15: 50 | I15: 2 | J15: Rabu | K15: 0.33333333 | L15: 0.41666667 | M15: Kuliah | N15: Kuliah Mimbar | O15: 19940609 | P15: =IFERROR(VLOOKUP(O15, 'Data Dosen'!$A$2:$B$3628, 2, FALSE), "") -> Dr. rer. nat. Cecilia Esti Nugraheni S.T., M.T. | Q15: =IF(COUNTIFS(O:O,O15,J:J,J15,K:K,"<"&L15,L:L,">"&K15)>1,"Jadwal Bentrok dengan baris lain","Tidak Bentrok") -> Tidak Bentrok | R15: Dosen | S15: 2 | T15: - | U15: - | V15: - | X15: Mariskha Tri Adithia S.Si., M.Sc., PDEng.
A16: 11 | B16: 2025 | C16: 1 | D16: AIF231105 | E16: =IFERROR(VLOOKUP(D16, 'Mata Kuliah'!$F$2:$H$2828, 2, FALSE), "") -> 4 | F16: =IFERROR(VLOOKUP(D16, 'Mata Kuliah'!$F$2:$H$2828, 3, FALSE), "") -> Matematika Diskret | G16: A | H16: 50 | I16: 1 | J16: Senin | K16: 0.33333333 | L16: 0.41666667 | M16: Kuliah | N16: Kuliah Mimbar | O16: 20100037 | P16: =IFERROR(VLOOKUP(O16, 'Data Dosen'!$A$2:$B$3628, 2, FALSE), "") -> Mariskha Tri Adithia S.Si., M.Sc., PDEng. | Q16: =IF(COUNTIFS(O:O,O16,J:J,J16,K:K,"<"&L16,L:L,">"&K16)>1,"Jadwal Bentrok dengan baris lain","Tidak Bentrok") -> Tidak Bentrok | R16: Dosen | S16: 2 | T16: - | U16: - | V16: - | X16: Mariskha Tri Adithia S.Si., M.Sc., PDEng.
A17: 13 | B17: 2025 | C17: 1 | D17: AIF231105 | E17: =IFERROR(VLOOKUP(D17, 'Mata Kuliah'!$F$2:$H$2828, 2, FALSE), "") -> 4 | F17: =IFERROR(VLOOKUP(D17, 'Mata Kuliah'!$F$2:$H$2828, 3, FALSE), "") -> Matematika Diskret | G17: B | H17: 50 | I17: 1 | J17: Senin | K17: 0.33333333 | L17: 0.41666667 | M17: Kuliah | N17: Kuliah Mimbar | O17: 20110100 | P17: =IFERROR(VLOOKUP(O17, 'Data Dosen'!$A$2:$B$3628, 2, FALSE), "") -> Natalia S.Si., M.Si. | Q17: =IF(COUNTIFS(O:O,O17,J:J,J17,K:K,"<"&L17,L:L,">"&K17)>1,"Jadwal Bentrok dengan baris lain","Tidak Bentrok") -> Tidak Bentrok | R17: Dosen | S17: 2 | T17: - | U17: - | V17: - | X17: Mariskha Tri Adithia S.Si., M.Sc., PDEng.
A18: 14 | B18: 2025 | C18: 1 | D18: AIF231105 | E18: =IFERROR(VLOOKUP(D18, 'Mata Kuliah'!$F$2:$H$2828, 2, FALSE), "") -> 4 | F18: =IFERROR(VLOOKUP(D18, 'Mata Kuliah'!$F$2:$H$2828, 3, FALSE), "") -> Matematika Diskret | G18: B | H18: 50 | I18: 2 | J18: Rabu | K18: 0.33333333 | L18: 0.41666667 | M18: Kuliah | N18: Kuliah Mimbar | O18: 20110100 | P18: =IFERROR(VLOOKUP(O18, 'Data Dosen'!$A$2:$B$3628, 2, FALSE), "") -> Natalia S.Si., M.Si. | Q18: =IF(COUNTIFS(O:O,O18,J:J,J18,K:K,"<"&L18,L:L,">"&K18)>1,"Jadwal Bentrok dengan baris lain","Tidak Bentrok") -> Tidak Bentrok | R18: Dosen | S18: 2 | T18: - | U18: - | V18: - | X18: Mariskha Tri Adithia S.Si., M.Sc., PDEng.
A19: 22 | B19: 2025 | C19: 1 | D19: AIF232101 | E19: =IFERROR(VLOOKUP(D19, 'Mata Kuliah'!$F$2:$H$2828, 2, FALSE), "") -> 2 | F19: =IFERROR(VLOOKUP(D19, 'Mata Kuliah'!$F$2:$H$2828, 3, FALSE), "") -> Matriks dan Ruang Vektor | G19: C | H19: 50 | I19: 1 | J19: Selasa | K19: 0.33333333 | L19: 0.41666667 | M19: Kuliah | N19: Kuliah Mimbar | O19: 19850271 | P19: =IFERROR(VLOOKUP(O19, 'Data Dosen'!$A$2:$B$3628, 2, FALSE), "") -> Rosa De Lima Endang Padmowati Dra., M.T. | Q19: =IF(COUNTIFS(O:O,O19,J:J,J19,K:K,"<"&L19,L:L,">"&K19)>1,"Jadwal Bentrok dengan baris lain","Tidak Bentrok") -> Tidak Bentrok | R19: Dosen | S19: 2 | T19: Umur | U19: - | V19: - | X19: Natalia S.Si., M.Si.
A20: 20 | B20: 2025 | C20: 1 | D20: AIF232101 | E20: =IFERROR(VLOOKUP(D20, 'Mata Kuliah'!$F$2:$H$2828, 2, FALSE), "") -> 2 | F20: =IFERROR(VLOOKUP(D20, 'Mata Kuliah'!$F$2:$H$2828, 3, FALSE), "") -> Matriks dan Ruang Vektor | G20: B | H20: 50 | I20: 1 | J20: Selasa | K20: 0.29166667 | L20: 0.375 | M20: Kuliah | N20: Kuliah Mimbar | O20: 20110100 | P20: =IFERROR(VLOOKUP(O20, 'Data Dosen'!$A$2:$B$3628, 2, FALSE), "") -> Natalia S.Si., M.Si. | Q20: =IF(COUNTIFS(O:O,O20,J:J,J20,K:K,"<"&L20,L:L,">"&K20)>1,"Jadwal Bentrok dengan baris lain","Tidak Bentrok") -> Tidak Bentrok | R20: Dosen | S20: 2 | T20: - | U20: - | V20: - | X20: Natalia S.Si., M.Si.
A21: 18 | B21: 2025 | C21: 1 | D21: AIF232101 | E21: =IFERROR(VLOOKUP(D21, 'Mata Kuliah'!$F$2:$H$2828, 2, FALSE), "") -> 2 | F21: =IFERROR(VLOOKUP(D21, 'Mata Kuliah'!$F$2:$H$2828, 3, FALSE), "") -> Matriks dan Ruang Vektor | G21: A | H21: 50 | I21: 1 | J21: Selasa | K21: 0.375 | L21: 0.45833333 | M21: Kuliah | N21: Kuliah Mimbar | O21: 20110100 | P21: =IFERROR(VLOOKUP(O21, 'Data Dosen'!$A$2:$B$3628, 2, FALSE), "") -> Natalia S.Si., M.Si. | Q21: =IF(COUNTIFS(O:O,O21,J:J,J21,K:K,"<"&L21,L:L,">"&K21)>1,"Jadwal Bentrok dengan baris lain","Tidak Bentrok") -> Tidak Bentrok | R21: Dosen | S21: 2 | T21: - | U21: - | V21: - | X21: Natalia S.Si., M.Si.
A22: 23 | B22: 2025 | C22: 1 | D22: AIF232101 | E22: =IFERROR(VLOOKUP(D22, 'Mata Kuliah'!$F$2:$H$2828, 2, FALSE), "") -> 2 | F22: =IFERROR(VLOOKUP(D22, 'Mata Kuliah'!$F$2:$H$2828, 3, FALSE), "") -> Matriks dan Ruang Vektor | G22: C | H22: 50 | I22: 2 | J22: Kamis | K22: 0.54166667 | L22: 0.625 | M22: Responsi | N22: Diskusi Kelompok | O22: 19850271 | P22: =IFERROR(VLOOKUP(O22, 'Data Dosen'!$A$2:$B$3628, 2, FALSE), "") -> Rosa De Lima Endang Padmowati Dra., M.T. | Q22: =IF(COUNTIFS(O:O,O22,J:J,J22,K:K,"<"&L22,L:L,">"&K22)>1,"Jadwal Bentrok dengan baris lain","Tidak Bentrok") -> Tidak Bentrok | R22: Dosen | S22: 1.5 | T22: Umur | U22: - | V22: - | X22: Natalia S.Si., M.Si.
A23: 21 | B23: 2025 | C23: 1 | D23: AIF232101 | E23: =IFERROR(VLOOKUP(D23, 'Mata Kuliah'!$F$2:$H$2828, 2, FALSE), "") -> 2 | F23: =IFERROR(VLOOKUP(D23, 'Mata Kuliah'!$F$2:$H$2828, 3, FALSE), "") -> Matriks dan Ruang Vektor | G23: B | H23: 50 | I23: 2 | J23: Kamis | K23: 0.41666667 | L23: 0.5 | M23: Responsi | N23: Diskusi Kelompok | O23: 20110100 | P23: =IFERROR(VLOOKUP(O23, 'Data Dosen'!$A$2:$B$3628, 2, FALSE), "") -> Natalia S.Si., M.Si. | Q23: =IF(COUNTIFS(O:O,O23,J:J,J23,K:K,"<"&L23,L:L,">"&K23)>1,"Jadwal Bentrok dengan baris lain","Tidak Bentrok") -> Tidak Bentrok | R23: Dosen | S23: 1.5 | T23: - | U23: - | V23: - | X23: Natalia S.Si., M.Si.
A24: 19 | B24: 2025 | C24: 1 | D24: AIF232101 | E24: =IFERROR(VLOOKUP(D24, 'Mata Kuliah'!$F$2:$H$2828, 2, FALSE), "") -> 2 | F24: =IFERROR(VLOOKUP(D24, 'Mata Kuliah'!$F$2:$H$2828, 3, FALSE), "") -> Matriks dan Ruang Vektor | G24: A | H24: 50 | I24: 2 | J24: Kamis | K24: 0.54166667 | L24: 0.625 | M24: Responsi | N24: Diskusi Kelompok | O24: 20110100 | P24: =IFERROR(VLOOKUP(O24, 'Data Dosen'!$A$2:$B$3628, 2, FALSE), "") -> Natalia S.Si., M.Si. | Q24: =IF(COUNTIFS(O:O,O24,J:J,J24,K:K,"<"&L24,L:L,">"&K24)>1,"Jadwal Bentrok dengan baris lain","Tidak Bentrok") -> Tidak Bentrok | R24: Dosen | S24: 1.5 | T24: - | U24: - | V24: - | X24: Natalia S.Si., M.Si.
A25: 29 | B25: 2025 | C25: 1 | D25: AIF232103 | E25: =IFERROR(VLOOKUP(D25, 'Mata Kuliah'!$F$2:$H$2828, 2, FALSE), "") -> 4 | F25: =IFERROR(VLOOKUP(D25, 'Mata Kuliah'!$F$2:$H$2828, 3, FALSE), "") -> Pemrograman Berorientasi Objek | G25: B | H25: 45 | I25: 3 | J25: Jumat | K25: 0.29166667 | L25: 0.375 | M25: Kuliah | N25: Kuliah Mimbar | O25: 20120010 | P25: =IFERROR(VLOOKUP(O25, 'Data Dosen'!$A$2:$B$3628, 2, FALSE), "") -> Pascal Alfadian Nugroho S.Kom., M.Comp. | Q25: =IF(COUNTIFS(O:O,O25,J:J,J25,K:K,"<"&L25,L:L,">"&K25)>1,"Jadwal Bentrok dengan baris lain","Tidak Bentrok") -> Tidak Bentrok | R25: Dosen | S25: 2 | T25: - | U25: - | V25: - | X25: Keenan Adiwijaya Leman S.T., M.T.
A26: 27 | B26: 2025 | C26: 1 | D26: AIF232103 | E26: =IFERROR(VLOOKUP(D26, 'Mata Kuliah'!$F$2:$H$2828, 2, FALSE), "") -> 4 | F26: =IFERROR(VLOOKUP(D26, 'Mata Kuliah'!$F$2:$H$2828, 3, FALSE), "") -> Pemrograman Berorientasi Objek | G26: B | H26: 45 | I26: 1 | J26: Senin | K26: 0.41666667 | L26: 0.5 | M26: Kuliah | N26: Kuliah Mimbar | O26: 20140323 | P26: =IFERROR(VLOOKUP(O26, 'Data Dosen'!$A$2:$B$3628, 2, FALSE), "") -> Aditya Bagoes Saputra S.T., M.T. | Q26: =IF(COUNTIFS(O:O,O26,J:J,J26,K:K,"<"&L26,L:L,">"&K26)>1,"Jadwal Bentrok dengan baris lain","Tidak Bentrok") -> Tidak Bentrok | R26: Dosen | S26: 2 | T26: - | U26: - | V26: - | X26: Keenan Adiwijaya Leman S.T., M.T.
... A28: 24 | B28: 2025 | C28: 1 | D28: AIF232103 | E28: =IFERROR(VLOOKUP(D28, 'Mata Kuliah'!$F$2:$H$2828, 2, FALSE), "") -> 4 | F28: =IFERROR(VLOOKUP(D28, 'Mata Kuliah'!$F$2:$H$2828, 3, FALSE), "") -> Pemrograman Berorientasi Objek | G28: A | H28: 35 | I28: 1 | J28: Senin | K28: 0.41666667 | L28: 0.5 | M28: Kuliah | N28: Kuliah Mimbar | O28: 20160127 | P28: =IFERROR(VLOOKUP(O28, 'Data Dosen'!$A$2:$B$3628, 2, FALSE), "") -> Keenan Adiwijaya Leman S.T., M.T. | Q28: =IF(COUNTIFS(O:O,O28,J:J,J28,K:K,"<"&L28,L:L,">"&K28)>1,"Jadwal Bentrok dengan baris lain","Tidak Bentrok") -> Tidak Bentrok | R28: Dosen | S28: 2 | T28: - | U28: - | V28: - | X28: Keenan Adiwijaya Leman S.T., M.T.
A29: 25 | B29: 2025 | C29: 1 | D29: AIF232103 | E29: =IFERROR(VLOOKUP(D29, 'Mata Kuliah'!$F$2:$H$2828, 2, FALSE), "") -> 4 | F29: =IFERROR(VLOOKUP(D29, 'Mata Kuliah'!$F$2:$H$2828, 3, FALSE), "") -> Pemrograman Berorientasi Objek | G29: A | H29: 35 | I29: 2 | J29: Rabu | K29: 0.625 | L29: 0.70833333 | M29: Praktikum | N29: Diskusi Kelompok | O29: 20030252 | P29: =IFERROR(VLOOKUP(O29, 'Data Dosen'!$A$2:$B$3628, 2, FALSE), "") -> Lionov Ph.D. | Q29: =IF(COUNTIFS(O:O,O29,J:J,J29,K:K,"<"&L29,L:L,">"&K29)>1,"Jadwal Bentrok dengan baris lain","Tidak Bentrok") -> Tidak Bentrok | R29: Dosen | S29: 1 | T29: - | U29: - | V29: - | W29: Lab. Komputasi IF 9016 | X29: Keenan Adiwijaya Leman S.T., M.T.
A30: 28 | B30: 2025 | C30: 1 | D30: AIF232103 | E30: =IFERROR(VLOOKUP(D30, 'Mata Kuliah'!$F$2:$H$2828, 2, FALSE), "") -> 4 | F30: =IFERROR(VLOOKUP(D30, 'Mata Kuliah'!$F$2:$H$2828, 3, FALSE), "") -> Pemrograman Berorientasi Objek | G30: B | H30: 45 | I30: 2 | J30: Rabu | K30: 0.625 | L30: 0.70833333 | M30: Praktikum | N30: Diskusi Kelompok | O30: 20120010 | P30: =IFERROR(VLOOKUP(O30, 'Data Dosen'!$A$2:$B$3628, 2, FALSE), "") -> Pascal Alfadian Nugroho S.Kom., M.Comp. | Q30: =IF(COUNTIFS(O:O,O30,J:J,J30,K:K,"<"&L30,L:L,">"&K30)>1,"Jadwal Bentrok dengan baris lain","Tidak Bentrok") -> Tidak Bentrok | R30: Dosen | S30: 1 | T30: - | U30: - | V30: - | W30: Lab. Komputasi IF 9017 | X30: Keenan Adiwijaya Leman S.T., M.T.
A31: 30 | B31: 2025 | C31: 1 | D31: AIF232105 | E31: =IFERROR(VLOOKUP(D31, 'Mata Kuliah'!$F$2:$H$2828, 2, FALSE), "") -> 3 | F31: =IFERROR(VLOOKUP(D31, 'Mata Kuliah'!$F$2:$H$2828, 3, FALSE), "") -> Struktur Diskret | G31: A | H31: 50 | I31: 1 | J31: Selasa | K31: 0.625 | L31: 0.75 | M31: Kuliah | N31: Kuliah Mimbar | O31: 19940609 | P31: =IFERROR(VLOOKUP(O31, 'Data Dosen'!$A$2:$B$3628, 2, FALSE), "") -> Dr. rer. nat. Cecilia Esti Nugraheni S.T., M.T. | Q31: =IF(COUNTIFS(O:O,O31,J:J,J31,K:K,"<"&L31,L:L,">"&K31)>1,"Jadwal Bentrok dengan baris lain","Tidak Bentrok") -> Tidak Bentrok | R31: Dosen | S31: 3 | T31: - | U31: - | V31: - | X31: Dr. rer. nat. Cecilia Esti Nugraheni S.T., M.T.
A32: 31 | B32: 2025 | C32: 1 | D32: AIF232105 | E32: =IFERROR(VLOOKUP(D32, 'Mata Kuliah'!$F$2:$H$2828, 2, FALSE), "") -> 3 | F32: =IFERROR(VLOOKUP(D32, 'Mata Kuliah'!$F$2:$H$2828, 3, FALSE), "") -> Struktur Diskret | G32: B | H32: 50 | I32: 1 | J32: Selasa | K32: 0.625 | L32: 0.75 | M32: Kuliah | N32: Kuliah Mimbar | O32: 20050254 | P32: =IFERROR(VLOOKUP(O32, 'Data Dosen'!$A$2:$B$3628, 2, FALSE), "") -> Luciana Abednego S.Kom., M.T. | Q32: =IF(COUNTIFS(O:O,O32,J:J,J32,K:K,"<"&L32,L:L,">"&K32)>1,"Jadwal Bentrok dengan baris lain","Tidak Bentrok") -> Tidak Bentrok | R32: Dosen | S32: 3 | T32: - | U32: - | V32: - | X32: Dr. rer. nat. Cecilia Esti Nugraheni S.T., M.T.
A33: 35 | B33: 2025 | C33: 1 | D33: AIF232107 | E33: =IFERROR(VLOOKUP(D33, 'Mata Kuliah'!$F$2:$H$2828, 2, FALSE), "") -> 4 | F33: =IFERROR(VLOOKUP(D33, 'Mata Kuliah'!$F$2:$H$2828, 3, FALSE), "") -> Algoritma dan Struktur Data | G33: B | H33: 35 | I33: 1 | J33: Senin | K33: 0.54166667 | L33: 0.625 | M33: Kuliah | N33: Kuliah Mimbar | O33: 20050254 | P33: =IFERROR(VLOOKUP(O33, 'Data Dosen'!$A$2:$B$3628, 2, FALSE), "") -> Luciana Abednego S.Kom., M.T. | Q33: =IF(COUNTIFS(O:O,O33,J:J,J33,K:K,"<"&L33,L:L,">"&K33)>1,"Jadwal Bentrok dengan baris lain","Tidak Bentrok") -> Tidak Bentrok | R33: Dosen | S33: 2 | T33: - | U33: - | V33: - | X33: Husnul Hakim S.Kom., M.T.
A34: 37 | B34: 2025 | C34: 1 | D34: AIF232107 | E34: =IFERROR(VLOOKUP(D34, 'Mata Kuliah'!$F$2:$H$2828, 2, FALSE), "") -> 4 | F34: =IFERROR(VLOOKUP(D34, 'Mata Kuliah'!$F$2:$H$2828, 3, FALSE), "") -> Algoritma dan Struktur Data | G34: B | H34: 35 | I34: 3 | J34: Jumat | K34: 0.54166667 | L34: 0.625 | M34: Kuliah | N34: Kuliah Mimbar | O34: 20050254 | P34: =IFERROR(VLOOKUP(O34, 'Data Dosen'!$A$2:$B$3628, 2, FALSE), "") -> Luciana Abednego S.Kom., M.T. | Q34: =IF(COUNTIFS(O:O,O34,J:J,J34,K:K,"<"&L34,L:L,">"&K34)>1,"Jadwal Bentrok dengan baris lain","Tidak Bentrok") -> Tidak Bentrok | R34: Dosen | S34: 2 | T34: - | U34: - | V34: - | X34: Husnul Hakim S.Kom., M.T.
A35: 32 | B35: 2025 | C35: 1 | D35: AIF232107 | E35: =IFERROR(VLOOKUP(D35, 'Mata Kuliah'!$F$2:$H$2828, 2, FALSE), "") -> 4 | F35: =IFERROR(VLOOKUP(D35, 'Mata Kuliah'!$F$2:$H$2828, 3, FALSE), "") -> Algoritma dan Struktur Data | G35: A | H35: 40 | I35: 1 | J35: Senin | K35: 0.54166667 | L35: 0.625 | M35: Kuliah | N35: Kuliah Mimbar | O35: 20130009 | P35: =IFERROR(VLOOKUP(O35, 'Data Dosen'!$A$2:$B$3628, 2, FALSE), "") -> Husnul Hakim S.Kom., M.T. | Q35: =IF(COUNTIFS(O:O,O35,J:J,J35,K:K,"<"&L35,L:L,">"&K35)>1,"Jadwal Bentrok dengan baris lain","Tidak Bentrok") -> Tidak Bentrok | R35: Dosen | S35: 2 | T35: - | U35: - | V35: - | X35: Husnul Hakim S.Kom., M.T.
A36: 34 | B36: 2025 | C36: 1 | D36: AIF232107 | E36: =IFERROR(VLOOKUP(D36, 'Mata Kuliah'!$F$2:$H$2828, 2, FALSE), "") -> 4 | F36: =IFERROR(VLOOKUP(D36, 'Mata Kuliah'!$F$2:$H$2828, 3, FALSE), "") -> Algoritma dan Struktur Data | G36: A | H36: 40 | I36: 3 | J36: Jumat | K36: 0.54166667 | L36: 0.625 | M36: Kuliah | N36: Kuliah Mimbar | O36: 20130009 | P36: =IFERROR(VLOOKUP(O36, 'Data Dosen'!$A$2:$B$3628, 2, FALSE), "") -> Husnul Hakim S.Kom., M.T. | Q36: =IF(COUNTIFS(O:O,O36,J:J,J36,K:K,"<"&L36,L:L,">"&K36)>1,"Jadwal Bentrok dengan baris lain","Tidak Bentrok") -> Tidak Bentrok | R36: Dosen | S36: 2 | T36: - | U36: - | V36: - | X36: Husnul Hakim S.Kom., M.T.
A37: 38 | B37: 2025 | C37: 1 | D37: AIF232107 | E37: =IFERROR(VLOOKUP(D37, 'Mata Kuliah'!$F$2:$H$2828, 2, FALSE), "") -> 4 | F37: =IFERROR(VLOOKUP(D37, 'Mata Kuliah'!$F$2:$H$2828, 3, FALSE), "") -> Algoritma dan Struktur Data | G37: C | H37: 35 | I37: 1 | J37: Senin | K37: 0.54166667 | L37: 0.625 | M37: Kuliah | N37: Kuliah Mimbar | O37: 20140323 | P37: =IFERROR(VLOOKUP(O37, 'Data Dosen'!$A$2:$B$3628, 2, FALSE), "") -> Aditya Bagoes Saputra S.T., M.T. | Q37: =IF(COUNTIFS(O:O,O37,J:J,J37,K:K,"<"&L37,L:L,">"&K37)>1,"Jadwal Bentrok dengan baris lain","Tidak Bentrok") -> Tidak Bentrok | R37: Dosen | S37: 2 | T37: - | U37: - | V37: - | X37: Husnul Hakim S.Kom., M.T.
A38: 40 | B38: 2025 | C38: 1 | D38: AIF232107 | E38: =IFERROR(VLOOKUP(D38, 'Mata Kuliah'!$F$2:$H$2828, 2, FALSE), "") -> 4 | F38: =IFERROR(VLOOKUP(D38, 'Mata Kuliah'!$F$2:$H$2828, 3, FALSE), "") -> Algoritma dan Struktur Data | G38: C | H38: 35 | I38: 3 | J38: Jumat | K38: 0.54166667 | L38: 0.625 | M38: Kuliah | N38: Kuliah Mimbar | O38: 20140323 | P38: =IFERROR(VLOOKUP(O38, 'Data Dosen'!$A$2:$B$3628, 2, FALSE), "") -> Aditya Bagoes Saputra S.T., M.T. | Q38: =IF(COUNTIFS(O:O,O38,J:J,J38,K:K,"<"&L38,L:L,">"&K38)>1,"Jadwal Bentrok dengan baris lain","Tidak Bentrok") -> Tidak Bentrok | R38: Dosen | S38: 2 | T38: - | U38: - | V38: - | X38: Husnul Hakim S.Kom., M.T.
A39: 33 | B39: 2025 | C39: 1 | D39: AIF232107 | E39: =IFERROR(VLOOKUP(D39, 'Mata Kuliah'!$F$2:$H$2828, 2, FALSE), "") -> 4 | F39: =IFERROR(VLOOKUP(D39, 'Mata Kuliah'!$F$2:$H$2828, 3, FALSE), "") -> Algoritma dan Struktur Data | G39: A | H39: 40 | I39: 2 | J39: Rabu | K39: 0.33333333 | L39: 0.41666667 | M39: Praktikum | N39: Diskusi Kelompok | O39: 20130009 | P39: =IFERROR(VLOOKUP(O39, 'Data Dosen'!$A$2:$B$3628, 2, FALSE), "") -> Husnul Hakim S.Kom., M.T. | Q39: =IF(COUNTIFS(O:O,O39,J:J,J39,K:K,"<"&L39,L:L,">"&K39)>1,"Jadwal Bentrok dengan baris lain","Tidak Bentrok") -> Tidak Bentrok | R39: Dosen | S39: 1 | T39: - | U39: - | V39: - | W39: Lab. Komputasi IF 9018 | X39: Husnul Hakim S.Kom., M.T.
A40: 39 | B40: 2025 | C40: 1 | D40: AIF232107 | E40: =IFERROR(VLOOKUP(D40, 'Mata Kuliah'!$F$2:$H$2828, 2, FALSE), "") -> 4 | F40: =IFERROR(VLOOKUP(D40, 'Mata Kuliah'!$F$2:$H$2828, 3, FALSE), "") -> Algoritma dan Struktur Data | G40: C | H40: 35 | I40: 2 | J40: Rabu | K40: 0.33333333 | L40: 0.41666667 | M40: Praktikum | N40: Diskusi Kelompok | O40: 20140307 | P40: =IFERROR(VLOOKUP(O40, 'Data Dosen'!$A$2:$B$3628, 2, FALSE), "") -> Adrian Aldo Bagaskara S.T. | Q40: =IF(COUNTIFS(O:O,O40,J:J,J40,K:K,"<"&L40,L:L,">"&K40)>1,"Jadwal Bentrok dengan baris lain","Tidak Bentrok") -> Tidak Bentrok | R40: Dosen | S40: 1 | T40: - | U40: - | V40: - | W40: Lab. Komputasi IF 9016 | X40: Husnul Hakim S.Kom., M.T.
A41: 36 | B41: 2025 | C41: 1 | D41: AIF232107 | E41: =IFERROR(VLOOKUP(D41, 'Mata Kuliah'!$F$2:$H$2828, 2, FALSE), "") -> 4 | F41: =IFERROR(VLOOKUP(D41, 'Mata Kuliah'!$F$2:$H$2828, 3, FALSE), "") -> Algoritma dan Struktur Data | G41: B | H41: 35 | I41: 2 | J41: Rabu | K41: 0.33333333 | L41: 0.41666667 | M41: Praktikum | N41: Diskusi Kelompok | O41: 20140323 | P41: =IFERROR(VLOOKUP(O41, 'Data Dosen'!$A$2:$B$3628, 2, FALSE), "") -> Aditya Bagoes Saputra S.T., M.T. | Q41: =IF(COUNTIFS(O:O,O41,J:J,J41,K:K,"<"&L41,L:L,">"&K41)>1,"Jadwal Bentrok dengan baris lain","Tidak Bentrok") -> Tidak Bentrok | R41: Dosen | S41: 1 | T41: - | U41: - | V41: - | W41: Lab. Komputasi IF 9017 | X41: Husnul Hakim S.Kom., M.T.
...

Sheet Mata Kuliah
A1: No | B1: Tahun Kurikulum | C1: Fakultas | D1: Program Studi | E1: Program | F1: Kode MK | G1: SKS | H1: Nama MK
A2: 1 | B2: 2023 | C2: Teknik | D2: Arsitektur | E2: Doktor | F2: ARS237142 | G2: 2 | H2: Bidang Kajian 01
A3: 2 | B3: 2023 | C3: Teknik | D3: Arsitektur | E3: Doktor | F3: ARS237152 | G3: 2 | H3: Bidang Kajian 02
A4: 3 | B4: 2023 | C4: Teknik | D4: Arsitektur | E4: Doktor | F4: ARS237162 | G4: 2 | H4: Bidang Kajian 03
A5: 4 | B5: 2023 | C5: Teknik | D5: Arsitektur | E5: Doktor | F5: ARS238124 | G5: 3 | H5: Kemajuan Penelitian Disertasi 02
A6: 5 | B6: 2023 | C6: Teknik | D6: Arsitektur | E6: Doktor | F6: ARS239115 | G6: 10 | H6: Kemajuan Penelitian Disertasi 03
A7: 6 | B7: 2023 | C7: Teknik | D7: Arsitektur | E7: Doktor | F7: ARS239116 | G7: 10 | H7: Kemajuan Penelitian Disertasi 03
A8: 7 | B8: 2023 | C8: Sains | D8: Informatika | E8: Sarjana | F8: AIF233110 | G8: 3 | H8: Kriptografi
A9: 8 | B9: 2023 | C9: Sains | D9: Informatika | E9: Sarjana | F9: AIF233119 | G9: 5 | H9: Kerja Praktik Computing Science 4
A10: 9 | B10: 2023 | C10: Sains | D10: Informatika | E10: Sarjana | F10: AIF234403 | G10: 3 | H10: Teknologi Penyimpanan dan Pemrosesan Big Data
A11: 10 | B11: 2023 | C11: Sains | D11: Informatika | E11: Sarjana | F11: AIF233314 | G11: 3 | H11: Kewirausahaan Berbasis Teknologi
A12: 11 | B12: 2023 | C12: Sains | D12: Informatika | E12: Sarjana | F12: AIF233211 | G12: 2 | H12: Topik Khusus Sistem Terdistribusi 1
A13: 12 | B13: 2023 | C13: Sains | D13: Informatika | E13: Sarjana | F13: AIF233208 | G13: 3 | H13: Topik Khusus Sistem Terdistribusi 2
... A2829: 2828 | B2829: 2023 | C2829: Keguruan dan Ilmu Pendidikan | D2829: Pendidikan Kimia | E2829: Sarjana | F2829: KIM234137 | G2829: 2 | H2829: Pengelolaan Laboratorium Kimia

Sheet Data Dosen
A1: NIK | B1: Nama Lengkap
A2: 19650015 | B2: Retnowulan Sutantio SH
A3: 19670169 | B3: Dr. Herlien Budiono SH.,MH
A4: 19730197 | B4: Djaja Sembiring Meliala S.H., M.H.
A5: 19740169 | B5: Dr. Hasan Mustafa Drs., M.S.
A6: 19740193 | B6: Djisman Samosir S.H., M.H.
A7: 19750011 | B7: Dr. Cecilia Lauw Giok Swan Ir., M.T.
A8: 19760179 | B8: Santoso Urip Gunawan Ir., M.T.
A9: 19780025 | B9: Prof. Dr. Johannes Gunawan SH., LL.M.
A10: 19780026 | B10: Noknik Karliya Herawati Dra., M.P.
A11: 19780027 | B11: Inge Barlian Dra., Akt., MSc.
A12: 19780029 | B12: Agus Hasan Pura Anggawidjaja Drs., M.Si.
A13: 19780030 | B13: Eduard Nurima Drs.,Ph.D
... A3629: 20250202 | B3629: Angelica Keisha Audrey Darmawan

Sheet List
A1: Bentuk Pembelajaran | C1: Jenis Pertemuan | E1: Jenis Dosen | G1: Hari | I1: Kebutuhan Khusus
A2: Asistensi Mengajar | C2: Kuliah Mimbar | E2: Dosen | G2: Senin | I2: Kursi Roda
A3: Kegiatan Wirausaha | C3: Diskusi Kelompok | E3: Asisten Dosen | G3: Selasa | I3: Tidak
A4: Kuliah | G4: Rabu | I4: Tunanetra
A5: Magang/praktek Kerja | G5: Kamis | I5: Umur
A6: Membangun Masyarakat/KKN tematik | G6: Jumat
A7: Pembelajaran Abdimas | G7: Sabtu
A8: Pembelajaran penelitian, perancangan / pengembangan | G8: Minggu
A9: Penelitian/riset
A10: Pertukaran Mahasiswa
A11: Praktik Bengkel
A12: Praktik Lapangan
A13: Praktik Studio
A14: Praktikum
A15: Proyek Kemanusiaan
A16: Responsi
A17: Seminar
A18: Studi/Proyek Independen
A19: Tutorial
